<?xml version="1.0" encoding="UTF-8"?>
<!-- Generated by org.testng.reporters.JUnitXMLReporter -->
<testsuite ignored="0" hostname="LFR-5CG31316P0" failures="1" tests="4" name="Test" time="224.48" errors="0" timestamp="2025-04-07T12:03:00 CEST">
  <testcase classname="RegressionPagesTestCase.FacturePageTest" name="AffichageErrorChampsNomPrenom_FR6777" time="74.508"/>
  <testcase classname="RegressionPagesTestCase.HomeRecPageTest" name="AffichageMessageErrorZeroResultat_6764" time="79.491"/>
  <testcase classname="RegressionPagesTestCase.FacturePageTest" name="ConnecterUtilisateur" time="68.357"/>
  <testcase classname="RegressionPagesTestCase.FacturePageTest" name="MontantNegatifTest" time="70.024">
    <failure type="java.lang.AssertionError" message="Le message d&amp;apos;erreur est affiché alors que le montant est valide ! expected [false] but found [true]">
      <![CDATA[java.lang.AssertionError: Le message d'erreur est affiché alors que le montant est valide ! expected [false] but found [true]
at RegressionPagesTestCase.FacturePageTest.MontantNegatifTest(FacturePageTest.java:31)
at java.base/java.util.concurrent.Executors$RunnableAdapter.call(Executors.java:572)
at java.base/java.util.concurrent.FutureTask.run(FutureTask.java:317)
at java.base/java.util.concurrent.ThreadPoolExecutor.runWorker(ThreadPoolExecutor.java:1144)
at java.base/java.util.concurrent.ThreadPoolExecutor$Worker.run(ThreadPoolExecutor.java:642)
at java.base/java.lang.Thread.run(Thread.java:1583)
... Removed 14 stack frames]]>
    </failure>
  </testcase> <!-- MontantNegatifTest -->
</testsuite> <!-- Test -->
